Workbook
Name Dates: 'CSE110'!$I:$L
Name DV_B: Setup!$E$2:$E$13
Name DV_D: Setup!$F$2:$F$9
Name DV_E: Setup!$G$2:$G$8
Name Dates: CSEPC110!$I:$L
Name Dates: CSEPC110M!$J:$M
Name Dates: 'CSE111'!$I:$L
Name Dates: 'CSE210'!$I:$L
Name Dates: 'CSE212'!$I:$L
Name Dates: 'CSE270'!$I:$L
Name Dates: 'CSE300'!$I:$L
Name Dates: 'CSE310'!$H:$K
Name Dates: 'CSE325'!$I:$L
Name Dates: 'CSE340'!$I:$L
Name Dates: 'CSE341'!$I:$L
Name Dates: 'CSE370'!$I:$L
Name Dates: 'CSE499'!$I:$L
Name Dates: 'ITM111'!$I:$L
Name Dates: 'WDD130'!$I:$L
Name Dates: 'WDD131'!$I:$L
Name Dates: 'WDD231'!$I:$L
Name Dates: 'WDD430'!$I:$L
Name Dates: 'WDD330'!$I:$L

Sheet Instructions START HERE
A2: . | C2: Preparing for the IMS

Sheet CSE110
A1: Course | B1: Action Type | C1: Assignment | D1: Week of Outreach | E1: Day of Outreach | F1: Points Possible | G1: % + or - for Outreach | H1: Configured | I1: Start Date | J1: Due Date | K1: Expire Date | L1: Score | M1: Reason for Outreach Title (Drop Down in IMS) | N1: Description/Prompt in IMS
A2: CSE110 | B2: New Student Added | C2: Novo Estudante Adicionado | D2: 0 | E2: 2 | H2: y | I2: =DATE(YEAR(Setup!$C$4),MONTH(Setup!$C$4),DAY(Setup!$C$4)+((D2-1)*7)+(E2-WEEKDAY(DATE(YEAR(Setup!$C$4),MONTH(Setup!$C$4),DAY(Setup!$C$4)),1))) | J2: =I2+3 | K2: =(I2 + (7 - WEEKDAY(I2,1))) + 1 | M2: Novo Aluno Adicionado | N2: Envie uma mensagem para os novos alunos para dar as boas-vindas à aula e ajudá-los a enviar as tarefas que perderam.
A3: CSE110 | B3: Quiz Question | C3: S01 - Questionário: Expectativas do Curso: Pergunta: Laptop 1 Resposta: Não | D3: 1 | E3: 2 | H3: y | I3: =DATE(YEAR(Setup!$C$4),MONTH(Setup!$C$4),DAY(Setup!$C$4)+((D3-1)*7)+(E3-WEEKDAY(DATE(YEAR(Setup!$C$4),MONTH(Setup!$C$4),DAY(Setup!$C$4)),1))) | J3: =I3+3 | K3: =(I3 + (7 - WEEKDAY(I3,1))) + 1 | L3: 0 | M3: Sem acesso a um computador | N3: Envie uma mensagem a cada aluno informando que eles não conseguirão ter sucesso neste curso sem um computador. Sugira que tranquem o curso e o façam quando tiverem acesso a um computador. (Consulte as Notas de Ensino para obter informações adicionais)
A4: CSE110 | B4: Scheduled - Not Logged In | C4: Não entrou no Canvas | D4: 1 | E4: 4 | H4: y | I4: =DATE(YEAR(Setup!$C$4),MONTH(Setup!$C$4),DAY(Setup!$C$4)+((D4-1)*7)+(E4-WEEKDAY(DATE(YEAR(Setup!$C$4),MONTH(Setup!$C$4),DAY(Setup!$C$4)),1))) | J4: =I4+3 | K4: =(I4 + (7 - WEEKDAY(I4,1))) + 1 | M4: Não acessou o Canvas | N4: Envie uma mensagem (fora do Canvas) para os estudantes que não fizeram login no Canvas, incentivando-os a fazer login antes da segunda-feira da Semana 2.
A5: CSE110 | B5: Missing Assignment | C5: S01 - Projeto: Histórias Inteligentes | D5: 2 | E5: 1 | H5: y | I5: =DATE(YEAR(Setup!$C$4),MONTH(Setup!$C$4),DAY(Setup!$C$4)+((D5-1)*7)+(E5-WEEKDAY(DATE(YEAR(Setup!$C$4),MONTH(Setup!$C$4),DAY(Setup!$C$4)),1))) | J5: =I5+3 | K5: =(I5 + (7 - WEEKDAY(I5,1))) + 1 | M5: Pendente: Projeto W01: Clever Stories | N5: Projeto da W01 Pendente: Clever Stories. Envie uma mensagem para entrar em contato com este aluno e incentivar o envio pontual da tarefa pendente
A6: CSE110 | B6: Quiz Question | C6: S01 - Reflexão: NeedHelp Resposta: Sim | D6: 2 | E6: 2 | H6: y | I6: =DATE(YEAR(Setup!$C$4),MONTH(Setup!$C$4),DAY(Setup!$C$4)+((D6-1)*7)+(E6-WEEKDAY(DATE(YEAR(Setup!$C$4),MONTH(Setup!$C$4),DAY(Setup!$C$4)),1))) | J6: =I6+3 | K6: =(I6 + (7 - WEEKDAY(I6,1))) + 1 | L6: 0 | M6: Resposta à Reflexão da W01 - O aluno respondeu que está sobrecarregado. | N6: O estudante respondeu que está se sentindo sobrecarregado na Reflexão da W01. Entre em contato com o estudante para ver como você pode ajudar.
A7: CSE110 | B7: Grader-Issued 0 | C7: S01 - Projeto: Histórias Inteligentes | D7: 2 | E7: 5 | H7: y | I7: =DATE(YEAR(Setup!$C$4),MONTH(Setup!$C$4),DAY(Setup!$C$4)+((D7-1)*7)+(E7-WEEKDAY(DATE(YEAR(Setup!$C$4),MONTH(Setup!$C$4),DAY(Setup!$C$4)),1))) | J7: =I7+3 | K7: =(I7 + (7 - WEEKDAY(I7,1))) + 1 | M7: Nota 0 atribuída pelo avaliador: Projeto W01 | N7: Este estudante recebeu um “0” atribuído pelo avaliador no Projeto W01. Isso provavelmente foi causado pelo envio de um modelo em branco, tarefa incorreta, uma versão plagiada da tarefa ou por apresentar dificuldades tão significativas que nenhum resultado de aprendizagem foi alcançado. Acesse o livro de notas do Canvas e revise as observações deixadas pelo avaliador. Envie uma mensagem para o estudante e trabalhe com ele para que a tarefa seja reenviada para avaliação.
A8: CSE110 | B8: High Performance | C8: S01 - Projeto: Histórias Inteligentes | D8: 2 | E8: 5 | F8: 100 | G8: 0.8 | H8: y | I8: =DATE(YEAR(Setup!$C$4),MONTH(Setup!$C$4),DAY(Setup!$C$4)+((D8-1)*7)+(E8-WEEKDAY(DATE(YEAR(Setup!$C$4),MONTH(Setup!$C$4),DAY(Setup!$C$4)),1))) | J8: =I8+3 | K8: =(I8 + (7 - WEEKDAY(I8,1))) + 1 | L8: =F8*G8 | M8: Alto Desempenho: Projeto da W01 | N8: Este aluno obteve 80% ou mais no W01 Projeto: Histórias Inteligentes. Envie uma mensagem de elogio e incentivo pelo esforço e bom desempenho nesta tarefa.
A9: CSE110 | B9: Low Performance | C9: S01 - Projeto: Histórias Inteligentes | D9: 2 | E9: 5 | F9: 100 | G9: 0.8 | H9: y | I9: =DATE(YEAR(Setup!$C$4),MONTH(Setup!$C$4),DAY(Setup!$C$4)+((D9-1)*7)+(E9-WEEKDAY(DATE(YEAR(Setup!$C$4),MONTH(Setup!$C$4),DAY(Setup!$C$4)),1))) | J9: =I9+3 | K9: =(I9 + (7 - WEEKDAY(I9,1))) + 1 | L9: =F9*G9 | M9: Resultados Não Atendidos: Projeto da W01 | N9: Este aluno obteve menos de 80% no Projeto da W01: Histórias Inteligentes. Envie uma mensagem para este aluno oferecendo alguma forma de ajuda para que ele(a) possa ter mais sucesso nesta tarefa e reenviá-la.
A10: CSE110 | B10: Missing Assignment | C10: S02 - Projeto: Calculadora de Preço de Refeições | D10: 3 | E10: 1 | H10: y | I10: =DATE(YEAR(Setup!$C$4),MONTH(Setup!$C$4),DAY(Setup!$C$4)+((D10-1)*7)+(E10-WEEKDAY(DATE(YEAR(Setup!$C$4),MONTH(Setup!$C$4),DAY(Setup!$C$4)),1))) | J10: =I10+3 | K10: =(I10 + (7 - WEEKDAY(I10,1))) + 1 | M10: Projeto da W02 Pendente: Meal Price Calculator | N10: Projeto da W02 pendente: Calculadora de Preço de Refeição. Envie uma mensagem para entrar em contato com este aluno e incentivar o envio pontual da tarefa pendente
A11: CSE110 | B11: Quiz Question | C11: S02 - Reflexão: NeedHelp Resposta: Sim | D11: 3 | E11: 2 | H11: y | I11: =DATE(YEAR(Setup!$C$4),MONTH(Setup!$C$4),DAY(Setup!$C$4)+((D11-1)*7)+(E11-WEEKDAY(DATE(YEAR(Setup!$C$4),MONTH(Setup!$C$4),DAY(Setup!$C$4)),1))) | J11: =I11+3 | K11: =(I11 + (7 - WEEKDAY(I11,1))) + 1 | L11: 0 | M11: Resposta à Reflexão da W02 - O aluno respondeu que está sobrecarregado. | N11: O(A) estudante respondeu que está se sentindo sobrecarregado(a) na Reflexão da W02. Entre em contato com o(a) estudante para ver como você pode ajudar.
A12: CSE110 | B12: Grader-Issued 0 | C12: S02 - Projeto: Calculadora de Preço de Refeições | D12: 3 | E12: 5 | H12: y | I12: =DATE(YEAR(Setup!$C$4),MONTH(Setup!$C$4),DAY(Setup!$C$4)+((D12-1)*7)+(E12-WEEKDAY(DATE(YEAR(Setup!$C$4),MONTH(Setup!$C$4),DAY(Setup!$C$4)),1))) | J12: =I12+3 | K12: =(I12 + (7 - WEEKDAY(I12,1))) + 1 | M12: Avaliador Atribuiu 0: Projeto da W02 | N12: Este aluno recebeu um “0” atribuído pelo avaliador no Projeto da W02. Isso provavelmente foi causado pelo envio de um modelo em branco, tarefa incorreta, uma versão plagiada da tarefa ou por apresentar dificuldades tão significativas que nenhum objetivo foi alcançado. Acesse o livro de notas do Canvas e revise as observações deixadas pelo avaliador. Envie uma mensagem ao aluno e colabore com ele para que a tarefa seja reenviada para avaliação.
A13: CSE110 | B13: High Performance | C13: S02 - Projeto: Calculadora de Preço de Refeições | D13: 3 | E13: 5 | F13: 100 | G13: 0.8 | H13: y | I13: =DATE(YEAR(Setup!$C$4),MONTH(Setup!$C$4),DAY(Setup!$C$4)+((D13-1)*7)+(E13-WEEKDAY(DATE(YEAR(Setup!$C$4),MONTH(Setup!$C$4),DAY(Setup!$C$4)),1))) | J13: =I13+3 | K13: =(I13 + (7 - WEEKDAY(I13,1))) + 1 | L13: =F13*G13 | M13: Alto desempenho: Projeto W02 | N13: Este estudante obteve nota de 80% ou mais no Projeto W02: Meat Price Calculator. Envie uma mensagem de elogio e incentivo pelo esforço e bom desempenho nesta tarefa.
A14: CSE110 | B14: Low Performance | C14: S02 - Projeto: Calculadora de Preço de Refeições | D14: 3 | E14: 5 | F14: 100 | G14: 0.8 | H14: y | I14: =DATE(YEAR(Setup!$C$4),MONTH(Setup!$C$4),DAY(Setup!$C$4)+((D14-1)*7)+(E14-WEEKDAY(DATE(YEAR(Setup!$C$4),MONTH(Setup!$C$4),DAY(Setup!$C$4)),1))) | J14: =I14+3 | K14: =(I14 + (7 - WEEKDAY(I14,1))) + 1 | L14: =F14*G14 | M14: Resultados Não Atingidos: Projeto W02 | N14: Este(a) estudante obteve menos de 80% no Projeto da W02: Calculadora de Preço de Refeição. Envie uma mensagem para este(a) estudante oferecendo algum tipo de ajuda para que ele/ela possa ter mais sucesso nesta tarefa e reenviá-la.
A15: CSE110 | B15: Missing Assignment | C15: S03 - Projeto: Jogo de Aventura | D15: 4 | E15: 1 | H15: y | I15: =DATE(YEAR(Setup!$C$4),MONTH(Setup!$C$4),DAY(Setup!$C$4)+((D15-1)*7)+(E15-WEEKDAY(DATE(YEAR(Setup!$C$4),MONTH(Setup!$C$4),DAY(Setup!$C$4)),1))) | J15: =I15+3 | K15: =(I15 + (7 - WEEKDAY(I15,1))) + 1 | M15: Projeto da W03 Pendente: Adventure Game | N15: Projeto W03 pendente: Jogo de Aventura. Envie uma mensagem para entrar em contato com este aluno e incentivar o envio pontual da tarefa pendente.
A16: CSE110 | B16: Quiz Question | C16: S03 - Reflexão: NeedHelp Resposta: Sim | D16: 4 | E16: 2 | H16: y | I16: =DATE(YEAR(Setup!$C$4),MONTH(Setup!$C$4),DAY(Setup!$C$4)+((D16-1)*7)+(E16-WEEKDAY(DATE(YEAR(Setup!$C$4),MONTH(Setup!$C$4),DAY(Setup!$C$4)),1))) | J16: =I16+3 | K16: =(I16 + (7 - WEEKDAY(I16,1))) + 1 | L16: 0 | M16: Resposta à Reflexão da W03 - O estudante respondeu que está sobrecarregado. | N16: O aluno respondeu na Reflexão W03 que está se sentindo sobrecarregado. Entre em contato com o aluno para ver como você pode ajudar.
A17: CSE110 | B17: Scheduled - Low Current Grade | C17: Lembrete de Prazo de Cancelamento | D17: 4 | E17: 4 | G17: 0.4 | H17: y | I17: =DATE(YEAR(Setup!$C$4),MONTH(Setup!$C$4),DAY(Setup!$C$4)+((D17-1)*7)+(E17-WEEKDAY(DATE(YEAR(Setup!$C$4),MONTH(Setup!$C$4),DAY(Setup!$C$4)),1))) | J17: =I17+3 | K17: =(I17 + (7 - WEEKDAY(I17,1))) + 1 | L17: 0 | M17: Aluno em situação de reprovação. Lembrete de cancelamento de matrícula | N17: Envie um e-mail para os alunos que estão reprovando no momento e que têm poucas chances de recuperação, lembrando-os do prazo de trancamento.
A18: CSE110 | B18: Grader-Issued 0 | C18: S03 - Projeto: Jogo de Aventura | D18: 4 | E18: 5 | H18: y | I18: =DATE(YEAR(Setup!$C$4),MONTH(Setup!$C$4),DAY(Setup!$C$4)+((D18-1)*7)+(E18-WEEKDAY(DATE(YEAR(Setup!$C$4),MONTH(Setup!$C$4),DAY(Setup!$C$4)),1))) | J18: =I18+3 | K18: =(I18 + (7 - WEEKDAY(I18,1))) + 1 | M18: Nota 0 atribuída pelo Corretor: Projeto da W03 | N18: Este aluno obteve um “0” atribuído pelo avaliador no Projeto da W03. Isso provavelmente foi causado pelo envio de um modelo em branco, tarefa incorreta, uma versão plagiada da tarefa ou por apresentar dificuldades tão significativas que nenhum objetivo foi alcançado. Acesse o livro de notas do Canvas e revise as observações deixadas pelo avaliador. Envie uma mensagem para o aluno e trabalhe com ele para que a tarefa seja reenviada para avaliação.
A19: CSE110 | B19: High Performance | C19: S03 - Projeto: Jogo de Aventura | D19: 4 | E19: 5 | F19: 100 | G19: 0.8 | H19: y | I19: =DATE(YEAR(Setup!$C$4),MONTH(Setup!$C$4),DAY(Setup!$C$4)+((D19-1)*7)+(E19-WEEKDAY(DATE(YEAR(Setup!$C$4),MONTH(Setup!$C$4),DAY(Setup!$C$4)),1))) | J19: =I19+3 | K19: =(I19 + (7 - WEEKDAY(I19,1))) + 1 | L19: =F19*G19 | M19: Alto Desempenho: Projeto da W03 | N19: Este aluno obteve nota igual ou superior a 80% no Projeto W03: Jogo de aventura. Envie uma mensagem de elogio e incentivo pelo esforço e bom desempenho nesta tarefa.
A20: CSE110 | B20: Low Performance | C20: S03 - Projeto: Jogo de Aventura | D20: 4 | E20: 5 | F20: 100 | G20: 0.8 | H20: y | I20: =DATE(YEAR(Setup!$C$4),MONTH(Setup!$C$4),DAY(Setup!$C$4)+((D20-1)*7)+(E20-WEEKDAY(DATE(YEAR(Setup!$C$4),MONTH(Setup!$C$4),DAY(Setup!$C$4)),1))) | J20: =I20+3 | K20: =(I20 + (7 - WEEKDAY(I20,1))) + 1 | L20: =F20*G20 | M20: Resultados Não Alcançados: W03 Projeto | N20: Este aluno obteve menos de 80% no Projeto da W03: Jogo de Aventura. Envie uma mensagem para este aluno oferecendo algum tipo de ajuda para que ele(a) possa ter mais sucesso nesta tarefa e reenviá-la.
A21: CSE110 | B21: Missing Assignment | C21: S04 - Projeto: Adivinhação de Palavras | D21: 5 | E21: 1 | H21: y | I21: =DATE(YEAR(Setup!$C$4),MONTH(Setup!$C$4),DAY(Setup!$C$4)+((D21-1)*7)+(E21-WEEKDAY(DATE(YEAR(Setup!$C$4),MONTH(Setup!$C$4),DAY(Setup!$C$4)),1))) | J21: =I21+3 | K21: =(I21 + (7 - WEEKDAY(I21,1))) + 1 | M21: Projeto W04 pendente: Quebra-Cabeça de Palavras | N21: Pendente: Projeto W04: Word Puzzle. Envie uma mensagem para verificar a situação deste estudante e incentivar o envio pontual da tarefa pendente
A22: CSE110 | B22: Quiz Question | C22: S04 - Reflexão: NeedHelp Resposta: Sim | D22: 5 | E22: 2 | H22: y | I22: =DATE(YEAR(Setup!$C$4),MONTH(Setup!$C$4),DAY(Setup!$C$4)+((D22-1)*7)+(E22-WEEKDAY(DATE(YEAR(Setup!$C$4),MONTH(Setup!$C$4),DAY(Setup!$C$4)),1))) | J22: =I22+3 | K22: =(I22 + (7 - WEEKDAY(I22,1))) + 1 | L22: 0 | M22: Resposta à Reflexão W04 - O aluno respondeu que está sobrecarregado. | N22: O(A) estudante respondeu que está se sentindo sobrecarregado(a) na Reflexão da W04. Entre em contato com o(a) estudante para ver como você pode ajudar.
A23: CSE110 | B23: Grader-Issued 0 | C23: S04 - Projeto: Adivinhação de Palavras | D23: 5 | E23: 5 | H23: y | I23: =DATE(YEAR(Setup!$C$4),MONTH(Setup!$C$4),DAY(Setup!$C$4)+((D23-1)*7)+(E23-WEEKDAY(DATE(YEAR(Setup!$C$4),MONTH(Setup!$C$4),DAY(Setup!$C$4)),1))) | J23: =I23+3 | K23: =(I23 + (7 - WEEKDAY(I23,1))) + 1 | M23: Nota 0 atribuída pelo avaliador: Projeto W04 | N23: Este estudante recebeu um “0” atribuído pelo avaliador no Projeto W04. Isso provavelmente foi causado pelo envio de um modelo em branco, tarefa incorreta, uma versão plagiada da tarefa ou por apresentar dificuldades tão significativas que nenhum resultado de aprendizagem foi alcançado. Acesse o livro de notas do Canvas e revise as observações deixadas pelo avaliador. Envie uma mensagem para o estudante e trabalhe com ele para que a tarefa seja reenviada para avaliação.
A24: CSE110 | B24: High Performance | C24: S04 - Projeto: Adivinhação de Palavras | D24: 5 | E24: 5 | F24: 100 | G24: 0.8 | H24: y | I24: =DATE(YEAR(Setup!$C$4),MONTH(Setup!$C$4),DAY(Setup!$C$4)+((D24-1)*7)+(E24-WEEKDAY(DATE(YEAR(Setup!$C$4),MONTH(Setup!$C$4),DAY(Setup!$C$4)),1))) | J24: =I24+3 | K24: =(I24 + (7 - WEEKDAY(I24,1))) + 1 | L24: =F24*G24 | M24: Alto desempenho: Projeto W04 | N24: Este aluno obteve nota igual ou superior a 80% no Projeto da W04: Quebra-cabeça de Palavras. Envie uma mensagem de elogio e incentivo pelo esforço e bom desempenho nesta tarefa.
A25: CSE110 | B25: Low Performance | C25: S04 - Projeto: Adivinhação de Palavras | D25: 5 | E25: 5 | F25: 100 | G25: 0.8 | H25: y | I25: =DATE(YEAR(Setup!$C$4),MONTH(Setup!$C$4),DAY(Setup!$C$4)+((D25-1)*7)+(E25-WEEKDAY(DATE(YEAR(Setup!$C$4),MONTH(Setup!$C$4),DAY(Setup!$C$4)),1))) | J25: =I25+3 | K25: =(I25 + (7 - WEEKDAY(I25,1))) + 1 | L25: =F25*G25 | M25: Resultados Não Atingidos: Projeto W04 | N25: Este aluno obteve nota inferior a 80% no Projeto da W04: Word Puzzle. Envie uma mensagem para este aluno oferecendo algum tipo de ajuda para que ele possa ter mais sucesso nesta tarefa e enviá-la novamente.
A26: CSE110 | B26: Missing Assignment | C26: S05 - Projeto: Carrinho de Compras | D26: 6 | E26: 1 | H26: y | I26: =DATE(YEAR(Setup!$C$4),MONTH(Setup!$C$4),DAY(Setup!$C$4)+((D26-1)*7)+(E26-WEEKDAY(DATE(YEAR(Setup!$C$4),MONTH(Setup!$C$4),DAY(Setup!$C$4)),1))) | J26: =I26+3 | K26: =(I26 + (7 - WEEKDAY(I26,1))) + 1 | M26: Projeto da W05 Pendente: Carrinho de Compras | N26: Pendente - Projeto da W05: Carrinho de Compras. Envie uma mensagem para entrar em contato com este aluno e incentivar o envio pontual da tarefa pendente
A27: CSE110 | B27: Quiz Question | C27: S05 - Reflexão: NeedHelp Resposta: Sim | D27: 6 | E27: 2 | H27: y | I27: =DATE(YEAR(Setup!$C$4),MONTH(Setup!$C$4),DAY(Setup!$C$4)+((D27-1)*7)+(E27-WEEKDAY(DATE(YEAR(Setup!$C$4),MONTH(Setup!$C$4),DAY(Setup!$C$4)),1))) | J27: =I27+3 | K27: =(I27 + (7 - WEEKDAY(I27,1))) + 1 | L27: 0 | M27: Resposta à Reflexão W05 - O aluno respondeu que está sobrecarregado. | N27: O aluno respondeu que está se sentindo sobrecarregado na Reflexão da W05. Entre em contato com o aluno para ver como pode ajudar.
A28: CSE110 | B28: Grader-Issued 0 | C28: S05 - Projeto: Carrinho de Compras | D28: 6 | E28: 5 | H28: y | I28: =DATE(YEAR(Setup!$C$4),MONTH(Setup!$C$4),DAY(Setup!$C$4)+((D28-1)*7)+(E28-WEEKDAY(DATE(YEAR(Setup!$C$4),MONTH(Setup!$C$4),DAY(Setup!$C$4)),1))) | J28: =I28+3 | K28: =(I28 + (7 - WEEKDAY(I28,1))) + 1 | M28: Avaliador atribuiu nota 0: Projeto W05 | N28: Este aluno recebeu um “0” atribuído pelo avaliador no Projeto W05. Isso provavelmente foi causado pelo envio de um modelo em branco, tarefa incorreta, uma versão plagiada da tarefa ou por apresentar tanta dificuldade que nenhum objetivo foi alcançado. Faça login no boletim de notas do Canvas e revise as observações deixadas pelo avaliador. Envie uma mensagem ao aluno e trabalhe com ele para que a tarefa seja enviada novamente para avaliação.
A29: CSE110 | B29: High Performance | C29: S05 - Projeto: Carrinho de Compras | D29: 6 | E29: 5 | F29: 100 | G29: 0.8 | H29: y | I29: =DATE(YEAR(Setup!$C$4),MONTH(Setup!$C$4),DAY(Setup!$C$4)+((D29-1)*7)+(E29-WEEKDAY(DATE(YEAR(Setup!$C$4),MONTH(Setup!$C$4),DAY(Setup!$C$4)),1))) | J29: =I29+3 | K29: =(I29 + (7 - WEEKDAY(I29,1))) + 1 | L29: =F29*G29 | M29: Alto Desempenho: Projeto da W05 | N29: Este aluno pontuou 80% ou mais no Projeto da W05: Carrinho de Compras. Envie uma mensagem de elogio e incentivo pelo esforço e bom desempenho nesta tarefa.
A30: CSE110 | B30: Low Performance | C30: S05 - Projeto: Carrinho de Compras | D30: 6 | E30: 5 | F30: 100 | G30: 0.8 | H30: y | I30: =DATE(YEAR(Setup!$C$4),MONTH(Setup!$C$4),DAY(Setup!$C$4)+((D30-1)*7)+(E30-WEEKDAY(DATE(YEAR(Setup!$C$4),MONTH(Setup!$C$4),DAY(Setup!$C$4)),1))) | J30: =I30+3 | K30: =(I30 + (7 - WEEKDAY(I30,1))) + 1 | L30: =F30*G30 | M30: Resultados Não Alcançados: W05 Projeto | N30: Este aluno obteve nota menor que 80% no Projeto W05: Carrinho de Compras. Envie uma mensagem para este aluno oferecendo alguma forma de ajuda para que ele/ela possa ter mais sucesso nesta tarefa e enviá-la novamente.
A31: CSE110 | B31: Scheduled - Classwide | C31: Lembrete de Encerramento do Curso | D31: 7 | E31: 1 | H31: y | I31: =DATE(YEAR(Setup!$C$4),MONTH(Setup!$C$4),DAY(Setup!$C$4)+((D31-1)*7)+(E31-WEEKDAY(DATE(YEAR(Setup!$C$4),MONTH(Setup!$C$4),DAY(Setup!$C$4)),1))) | J31: =I31+3 | K31: =(I31 + (7 - WEEKDAY(I31,1))) + 1 | M31: Lembrete de Encerramento do Curso | N31: Envie uma mensagem aos seus alunos, lembrando-os de que o curso se encerra esta semana e sobre os prazos que devem cumprir para entregar as tarefas e aplicá-las à nota final.
A32: CSE110 | B32: Scheduled - Classwide | C32: Lembrete de Inscrição 2 | D32: 7 | E32: 1 | H32: y | I32: =DATE(YEAR(Setup!$C$4),MONTH(Setup!$C$4),DAY(Setup!$C$4)+((D32-1)*7)+(E32-WEEKDAY(DATE(YEAR(Setup!$C$4),MONTH(Setup!$C$4),DAY(Setup!$C$4)),1))) | J32: =I32+3 | K32: =(I32 + (7 - WEEKDAY(I32,1))) + 1 | L32: 0 | M32: Lembrete de Matrícula 2 | N32: Envie uma mensagem a todos os alunos, lembrando-os de que as inscrições para o próximo bloco ainda estão abertas, mas serão encerradas em breve. Incentive-os a acessar o sistema e se inscrever o quanto antes.
A33: CSE110 | B33: Scheduled - Classwide | C33: Lembrete de Fim de Bloco | D33: 7 | E33: 2 | H33: y | I33: =DATE(YEAR(Setup!$C$4),MONTH(Setup!$C$4),DAY(Setup!$C$4)+((D33-1)*7)+(E33-WEEKDAY(DATE(YEAR(Setup!$C$4),MONTH(Setup!$C$4),DAY(Setup!$C$4)),1))) | J33: =I33+3 | K33: =(I33 + (7 - WEEKDAY(I33,1))) + 1 | M33: Lembrete de Fim de Bloco | N33: Lembre os alunos de que o curso será encerrado, para enviarem as tarefas dentro do prazo e preencherem a Avaliação de Fim de Curso

Sheet CSEPC110
A1: Course | B1: Action Type | C1: Assignment | D1: Week of Outreach | E1: Day of Outreach | F1: Points Possible | G1: % + or - for Outreach | H1: Configured | I1: Start Date | J1: Due Date | K1: Expire Date | L1: Score | M1: Reason for Outreach Title (Drop Down in IMS) | N1: Description/Prompt in IMS
A2: CSEPC110 | B2: New Student Added | C2: New Student Added | D2: 0 | E2: 2 | H2: y | I2: =DATE(YEAR(Setup!$C$4),MONTH(Setup!$C$4),DAY(Setup!$C$4)+((D2-1)*7)+(E2-WEEKDAY(DATE(YEAR(Setup!$C$4),MONTH(Setup!$C$4),DAY(Setup!$C$4)),1))) | J2: =I2+3 | K2: =(I2 + (7 - WEEKDAY(I2,1))) + 1 | M2: New Student Added | N2: Send a message to new students to welcome them to class and help them submit any assignments they missed.
A3: CSEPC110 | B3: Quiz Question | C3: W01 Quiz: Course Expectations: Question: Laptop Answer: No | D3: 1 | E3: 2 | H3: y | I3: =DATE(YEAR(Setup!$C$4),MONTH(Setup!$C$4),DAY(Setup!$C$4)+((D3-1)*7)+(E3-WEEKDAY(DATE(YEAR(Setup!$C$4),MONTH(Setup!$C$4),DAY(Setup!$C$4)),1))) | J3: =I3+3 | K3: =(I3 + (7 - WEEKDAY(I3,1))) + 1 | L3: 0 | M3: No access to a computer | N3: Send a message to each student letting them know that they cannot be successful in this course without a computer. Suggest they drop the course and take it when they have access to a computer. (See Teaching notes for additional information)
A4: CSEPC110 | B4: Scheduled - Not Logged In | C4: Not Logged into Canvas | D4: 1 | E4: 4 | H4: y | I4: =DATE(YEAR(Setup!$C$4),MONTH(Setup!$C$4),DAY(Setup!$C$4)+((D4-1)*7)+(E4-WEEKDAY(DATE(YEAR(Setup!$C$4),MONTH(Setup!$C$4),DAY(Setup!$C$4)),1))) | J4: =I4+3 | K4: =(I4 + (7 - WEEKDAY(I4,1))) + 1 | M4: Not Logged Into Canvas | N4: Send a message (outside of Canvas) to students who have not logged into Canvas encouraging them to log in before Monday of Week 2.
A5: CSEPC110 | B5: Missing Assignment | C5: W01 Project: Clever Stories | D5: 2 | E5: 1 | H5: y | I5: =DATE(YEAR(Setup!$C$4),MONTH(Setup!$C$4),DAY(Setup!$C$4)+((D5-1)*7)+(E5-WEEKDAY(DATE(YEAR(Setup!$C$4),MONTH(Setup!$C$4),DAY(Setup!$C$4)),1))) | J5: =I5+3 | K5: =(I5 + (7 - WEEKDAY(I5,1))) + 1 | M5: Missing W01 Project: Clever Stories | N5: Missing W01 Project: Clever Stories. Send a message to check in with this student and encourage timely submission of the missing assignment
A6: CSEPC110 | B6: Quiz Question | C6: W01 Reflection: NeedHelp Answer: Yes | D6: 2 | E6: 2 | H6: y | I6: =DATE(YEAR(Setup!$C$4),MONTH(Setup!$C$4),DAY(Setup!$C$4)+((D6-1)*7)+(E6-WEEKDAY(DATE(YEAR(Setup!$C$4),MONTH(Setup!$C$4),DAY(Setup!$C$4)),1))) | J6: =I6+3 | K6: =(I6 + (7 - WEEKDAY(I6,1))) + 1 | L6: 0 | M6: Response to W01 Reflection - Student responded they are overwhelmed. | N6: Student responded feeling overwhelmed to W01 Reflection. Reach out to student to see how you can help.
A7: CSEPC110 | B7: Grader-Issued 0 | C7: W01 Project: Clever Stories | D7: 2 | E7: 5 | H7: y | I7: =DATE(YEAR(Setup!$C$4),MONTH(Setup!$C$4),DAY(Setup!$C$4)+((D7-1)*7)+(E7-WEEKDAY(DATE(YEAR(Setup!$C$4),MONTH(Setup!$C$4),DAY(Setup!$C$4)),1))) | J7: =I7+3 | K7: =(I7 + (7 - WEEKDAY(I7,1))) + 1 | M7: Grader Issued 0: W01 Project | N7: This student received a grader-issued “0” on the W01 Project. This is likely caused by the student submitting a blank template, wrong assignment, a plagiarized version of the assignment, or struggling so significantly that no outcomes were met. Log into Canvas gradebook and review notes left by the grader. Send a message to the student and work with the student to get the assignment resubmitted for grading.
A8: CSEPC110 | B8: High Performance | C8: W01 Project: Clever Stories | D8: 2 | E8: 5 | F8: 100 | G8: 0.8 | H8: y | I8: =DATE(YEAR(Setup!$C$4),MONTH(Setup!$C$4),DAY(Setup!$C$4)+((D8-1)*7)+(E8-WEEKDAY(DATE(YEAR(Setup!$C$4),MONTH(Setup!$C$4),DAY(Setup!$C$4)),1))) | J8: =I8+3 | K8: =(I8 + (7 - WEEKDAY(I8,1))) + 1 | L8: =F8*G8 | M8: High-Performance: W01 Project | N8: This student scored 80% or higher on the W01 Project: Clever Stories. Send a message of praise and encouragement for effort and good performance on this assignment.
A9: CSEPC110 | B9: Low Performance | C9: W01 Project: Clever Stories | D9: 2 | E9: 5 | F9: 100 | G9: 0.8 | H9: y | I9: =DATE(YEAR(Setup!$C$4),MONTH(Setup!$C$4),DAY(Setup!$C$4)+((D9-1)*7)+(E9-WEEKDAY(DATE(YEAR(Setup!$C$4),MONTH(Setup!$C$4),DAY(Setup!$C$4)),1))) | J9: =I9+3 | K9: =(I9 + (7 - WEEKDAY(I9,1))) + 1 | L9: =F9*G9 | M9: Outcomes Not Met: W01 Project | N9: This student scored less than 80% on the W01 Project: Clever Stories. Send a message to this student offering some form of help so he/she can be more successful on this assignment and resubmit.
A10: CSEPC110 | B10: Missing Assignment | C10: W02 Project: Meal Price Calculator | D10: 3 | E10: 1 | H10: y | I10: =DATE(YEAR(Setup!$C$4),MONTH(Setup!$C$4),DAY(Setup!$C$4)+((D10-1)*7)+(E10-WEEKDAY(DATE(YEAR(Setup!$C$4),MONTH(Setup!$C$4),DAY(Setup!$C$4)),1))) | J10: =I10+3 | K10: =(I10 + (7 - WEEKDAY(I10,1))) + 1 | M10: Missing W02 Project: Meal Price Calculator | N10: Missing W02 Project: Meal Price Calculator. Send a message to check in with this student and encourage timely submission of the missing assignment
A11: CSEPC110 | B11: Quiz Question | C11: W02 Reflection: NeedHelp Answer: Yes | D11: 3 | E11: 2 | H11: y | I11: =DATE(YEAR(Setup!$C$4),MONTH(Setup!$C$4),DAY(Setup!$C$4)+((D11-1)*7)+(E11-WEEKDAY(DATE(YEAR(Setup!$C$4),MONTH(Setup!$C$4),DAY(Setup!$C$4)),1))) | J11: =I11+3 | K11: =(I11 + (7 - WEEKDAY(I11,1))) + 1 | L11: 0 | M11: Response to W02 Reflection - Student responded they are overwhelmed. | N11: Student responded feeling overwhelmed to W02 Reflection. Reach out to student to see how you can help.
A12: CSEPC110 | B12: Grader-Issued 0 | C12: W02 Project: Meal Price Calculator | D12: 3 | E12: 5 | H12: y | I12: =DATE(YEAR(Setup!$C$4),MONTH(Setup!$C$4),DAY(Setup!$C$4)+((D12-1)*7)+(E12-WEEKDAY(DATE(YEAR(Setup!$C$4),MONTH(Setup!$C$4),DAY(Setup!$C$4)),1))) | J12: =I12+3 | K12: =(I12 + (7 - WEEKDAY(I12,1))) + 1 | M12: Grader Issued 0: W02 Project | N12: This student received a grader-issued “0” on the W02 Project. This is likely caused by the student submitting a blank template, wrong assignment, a plagiarized version of the assignment, or struggling so significantly that no outcomes were met. Log into Canvas gradebook and review notes left by the grader. Send a message to the student and work with the student to get the assignment resubmitted for grading.
A13: CSEPC110 | B13: High Performance | C13: W02 Project: Meal Price Calculator | D13: 3 | E13: 5 | F13: 100 | G13: 0.8 | H13: y | I13: =DATE(YEAR(Setup!$C$4),MONTH(Setup!$C$4),DAY(Setup!$C$4)+((D13-1)*7)+(E13-WEEKDAY(DATE(YEAR(Setup!$C$4),MONTH(Setup!$C$4),DAY(Setup!$C$4)),1))) | J13: =I13+3 | K13: =(I13 + (7 - WEEKDAY(I13,1))) + 1 | L13: =F13*G13 | M13: High-Performance: W02 Project | N13: This student scored 80% or higher on the W02 Project: Meat Price Calculator. Send a message of praise and encouragement for effort and good performance on this assignment.
A14: CSEPC110 | B14: Low Performance | C14: W02 Project: Meal Price Calculator | D14: 3 | E14: 5 | F14: 100 | G14: 0.8 | H14: y | I14: =DATE(YEAR(Setup!$C$4),MONTH(Setup!$C$4),DAY(Setup!$C$4)+((D14-1)*7)+(E14-WEEKDAY(DATE(YEAR(Setup!$C$4),MONTH(Setup!$C$4),DAY(Setup!$C$4)),1))) | J14: =I14+3 | K14: =(I14 + (7 - WEEKDAY(I14,1))) + 1 | L14: =F14*G14 | M14: Outcomes Not Met: W02 Project | N14: This student scored less than 80% on the W02 Project: Meal Price Calculator. Send a message to this student offering some form of help so he/she can be more successful on this assignment and resubmit.
A15: CSEPC110 | B15: Missing Assignment | C15: W03 Project: Adventure Game | D15: 4 | E15: 1 | H15: y | I15: =DATE(YEAR(Setup!$C$4),MONTH(Setup!$C$4),DAY(Setup!$C$4)+((D15-1)*7)+(E15-WEEKDAY(DATE(YEAR(Setup!$C$4),MONTH(Setup!$C$4),DAY(Setup!$C$4)),1))) | J15: =I15+3 | K15: =(I15 + (7 - WEEKDAY(I15,1))) + 1 | M15: Missing W03 Project: Adventure Game | N15: Missing W03 Project: Adventure Game. Send a message to check in with this student and encourage timely submission of the missing assignment
A16: CSEPC110 | B16: Quiz Question | C16: W03 Reflection: NeedHelp Answer: Yes | D16: 4 | E16: 2 | H16: y | I16: =DATE(YEAR(Setup!$C$4),MONTH(Setup!$C$4),DAY(Setup!$C$4)+((D16-1)*7)+(E16-WEEKDAY(DATE(YEAR(Setup!$C$4),MONTH(Setup!$C$4),DAY(Setup!$C$4)),1))) | J16: =I16+3 | K16: =(I16 + (7 - WEEKDAY(I16,1))) + 1 | L16: 0 | M16: Response to W03 Reflection - Student responded they are overwhelmed. | N16: Student responded feeling overwhelmed to W03 Reflection. Reach out to student to see how you can help.
A17: CSEPC110 | B17: Scheduled - Low Current Grade | C17: Withdraw Deadline Reminder | D17: 4 | E17: 4 | H17: y | I17: =DATE(YEAR(Setup!$C$4),MONTH(Setup!$C$4),DAY(Setup!$C$4)+((D17-1)*7)+(E17-WEEKDAY(DATE(YEAR(Setup!$C$4),MONTH(Setup!$C$4),DAY(Setup!$C$4)),1))) | J17: =I17+3 | K17: =(I17 + (7 - WEEKDAY(I17,1))) + 1 | L17: 0 | M17: Failing student. Withdraw Reminder | N17: Email students who are currently failing with little chance to catch up, reminding them of the withdraw deadline.
A18: CSEPC110 | B18: Grader-Issued 0 | C18: W03 Project: Adventure Game | D18: 4 | E18: 5 | H18: y | I18: =DATE(YEAR(Setup!$C$4),MONTH(Setup!$C$4),DAY(Setup!$C$4)+((D18-1)*7)+(E18-WEEKDAY(DATE(YEAR(Setup!$C$4),MONTH(Setup!$C$4),DAY(Setup!$C$4)),1))) | J18: =I18+3 | K18: =(I18 + (7 - WEEKDAY(I18,1))) + 1 | M18: Grader Issued 0: W03 Project | N18: This student received a grader-issued “0” on the W03 Project. This is likely caused by the student submitting a blank template, wrong assignment, a plagiarized version of the assignment, or struggling so significantly that no outcomes were met. Log into Canvas gradebook and review notes left by the grader. Send a message to the student and work with the student to get the assignment resubmitted for grading.
A19: CSEPC110 | B19: High Performance | C19: W03 Project: Adventure Game | D19: 4 | E19: 5 | F19: 100 | G19: 0.8 | H19: y | I19: =DATE(YEAR(Setup!$C$4),MONTH(Setup!$C$4),DAY(Setup!$C$4)+((D19-1)*7)+(E19-WEEKDAY(DATE(YEAR(Setup!$C$4),MONTH(Setup!$C$4),DAY(Setup!$C$4)),1))) | J19: =I19+3 | K19: =(I19 + (7 - WEEKDAY(I19,1))) + 1 | L19: =F19*G19 | M19: High-Performance: W03 Project | N19: This student scored 80% or higher on the W03 Project: Adventure Game. Send a message of praise and encouragement for effort and good performance on this assignment.
A20: CSEPC110 | B20: Low Performance | C20: W03 Project: Adventure Game | D20: 4 | E20: 5 | F20: 100 | G20: 0.8 | H20: y | I20: =DATE(YEAR(Setup!$C$4),MONTH(Setup!$C$4),DAY(Setup!$C$4)+((D20-1)*7)+(E20-WEEKDAY(DATE(YEAR(Setup!$C$4),MONTH(Setup!$C$4),DAY(Setup!$C$4)),1))) | J20: =I20+3 | K20: =(I20 + (7 - WEEKDAY(I20,1))) + 1 | L20: =F20*G20 | M20: Outcomes Not Met: W03 Project | N20: This student scored less than 80% on the W03 Project: Adventure Game. Send a message to this student offering some form of help so he/she can be more successful on this assignment and resubmit.
A21: CSEPC110 | B21: Missing Assignment | C21: W04 Project: Word Puzzle | D21: 5 | E21: 1 | H21: y | I21: =DATE(YEAR(Setup!$C$4),MONTH(Setup!$C$4),DAY(Setup!$C$4)+((D21-1)*7)+(E21-WEEKDAY(DATE(YEAR(Setup!$C$4),MONTH(Setup!$C$4),DAY(Setup!$C$4)),1))) | J21: =I21+3 | K21: =(I21 + (7 - WEEKDAY(I21,1))) + 1 | M21: Missing W04 Project: Word Puzzle | N21: Missing W04 Project: Word Puzzle. Send a message to check in with this student and encourage timely submission of the missing assignment
A22: CSEPC110 | B22: Quiz Question | C22: W04 Reflection: NeedHelp Answer: Yes | D22: 5 | E22: 2 | H22: y | I22: =DATE(YEAR(Setup!$C$4),MONTH(Setup!$C$4),DAY(Setup!$C$4)+((D22-1)*7)+(E22-WEEKDAY(DATE(YEAR(Setup!$C$4),MONTH(Setup!$C$4),DAY(Setup!$C$4)),1))) | J22: =I22+3 | K22: =(I22 + (7 - WEEKDAY(I22,1))) + 1 | L22: 0 | M22: Response to W04 Reflection - Student responded they are overwhelmed. | N22: Student responded feeling overwhelmed to W04 Reflection. Reach out to student to see how you can help.
A23: CSEPC110 | B23: Grader-Issued 0 | C23: W04 Project: Word Puzzle | D23: 5 | E23: 5 | H23: y | I23: =DATE(YEAR(Setup!$C$4),MONTH(Setup!$C$4),DAY(Setup!$C$4)+((D23-1)*7)+(E23-WEEKDAY(DATE(YEAR(Setup!$C$4),MONTH(Setup!$C$4),DAY(Setup!$C$4)),1))) | J23: =I23+3 | K23: =(I23 + (7 - WEEKDAY(I23,1))) + 1 | M23: Grader Issued 0: W04 Project | N23: This student received a grader-issued “0” on the W04 Project. This is likely caused by the student submitting a blank template, wrong assignment, a plagiarized version of the assignment, or struggling so significantly that no outcomes were met. Log into Canvas gradebook and review notes left by the grader. Send a message to the student and work with the student to get the assignment resubmitted for grading.
A24: CSEPC110 | B24: High Performance | C24: W04 Project: Word Puzzle | D24: 5 | E24: 5 | F24: 100 | G24: 0.8 | H24: y | I24: =DATE(YEAR(Setup!$C$4),MONTH(Setup!$C$4),DAY(Setup!$C$4)+((D24-1)*7)+(E24-WEEKDAY(DATE(YEAR(Setup!$C$4),MONTH(Setup!$C$4),DAY(Setup!$C$4)),1))) | J24: =I24+3 | K24: =(I24 + (7 - WEEKDAY(I24,1))) + 1 | L24: =F24*G24 | M24: High-Performance: W04 Project | N24: This student scored 80% or higher on the W04 Project: Word Puzzle. Send a message of praise and encouragement for effort and good performance on this assignment.
A25: CSEPC110 | B25: Low Performance | C25: W04 Project: Word Puzzle | D25: 5 | E25: 5 | F25: 100 | G25: 0.8 | H25: y | I25: =DATE(YEAR(Setup!$C$4),MONTH(Setup!$C$4),DAY(Setup!$C$4)+((D25-1)*7)+(E25-WEEKDAY(DATE(YEAR(Setup!$C$4),MONTH(Setup!$C$4),DAY(Setup!$C$4)),1))) | J25: =I25+3 | K25: =(I25 + (7 - WEEKDAY(I25,1))) + 1 | L25: =F25*G25 | M25: Outcomes Not Met: W04 Project | N25: This student scored less than 80% on the W04 Project: Word Puzzle. Send a message to this student offering some form of help so he/she can be more successful on this assignment and resubmit.
A26: CSEPC110 | B26: Missing Assignment | C26: W05 Project: Shopping Cart | D26: 6 | E26: 1 | H26: y | I26: =DATE(YEAR(Setup!$C$4),MONTH(Setup!$C$4),DAY(Setup!$C$4)+((D26-1)*7)+(E26-WEEKDAY(DATE(YEAR(Setup!$C$4),MONTH(Setup!$C$4),DAY(Setup!$C$4)),1))) | J26: =I26+3 | K26: =(I26 + (7 - WEEKDAY(I26,1))) + 1 | M26: Missing W05 Project: Shopping Cart | N26: Missing W05 Project: Shopping Cart. Send a message to check in with this student and encourage timely submission of the missing assignment
A27: CSEPC110 | B27: Quiz Question | C27: W05 Reflection: NeedHelp Answer: Yes | D27: 6 | E27: 2 | H27: y | I27: =DATE(YEAR(Setup!$C$4),MONTH(Setup!$C$4),DAY(Setup!$C$4)+((D27-1)*7)+(E27-WEEKDAY(DATE(YEAR(Setup!$C$4),MONTH(Setup!$C$4),DAY(Setup!$C$4)),1))) | J27: =I27+3 | K27: =(I27 + (7 - WEEKDAY(I27,1))) + 1 | L27: 0 | M27: Response to W05 Reflection - Student responded they are overwhelmed. | N27: Student responded feeling overwhelmed to W05 Reflection. Reach out to student to see how you can help.
A28: CSEPC110 | B28: Grader-Issued 0 | C28: W05 Project: Shopping Cart | D28: 6 | E28: 5 | H28: y | I28: =DATE(YEAR(Setup!$C$4),MONTH(Setup!$C$4),DAY(Setup!$C$4)+((D28-1)*7)+(E28-WEEKDAY(DATE(YEAR(Setup!$C$4),MONTH(Setup!$C$4),DAY(Setup!$C$4)),1))) | J28: =I28+3 | K28: =(I28 + (7 - WEEKDAY(I28,1))) + 1 | M28: Grader Issued 0: W05 Project | N28: This student received a grader-issued “0” on the W05 Project. This is likely caused by the student submitting a blank template, wrong assignment, a plagiarized version of the assignment, or struggling so significantly that no outcomes were met. Log into Canvas gradebook and review notes left by the grader. Send a message to the student and work with the student to get the assignment resubmitted for grading.
A29: CSEPC110 | B29: High Performance | C29: W05 Project: Shopping Cart | D29: 6 | E29: 5 | F29: 100 | G29: 0.8 | H29: y | I29: =DATE(YEAR(Setup!$C$4),MONTH(Setup!$C$4),DAY(Setup!$C$4)+((D29-1)*7)+(E29-WEEKDAY(DATE(YEAR(Setup!$C$4),MONTH(Setup!$C$4),DAY(Setup!$C$4)),1))) | J29: =I29+3 | K29: =(I29 + (7 - WEEKDAY(I29,1))) + 1 | L29: =F29*G29 | M29: High-Performance: W05 Project | N29: This student scored 80% or higher on the W05 Project: Shopping Cart. Send a message of praise and encouragement for effort and good performance on this assignment.
A30: CSEPC110 | B30: Low Performance | C30: W05 Project: Shopping Cart | D30: 6 | E30: 5 | F30: 100 | G30: 0.8 | H30: y | I30: =DATE(YEAR(Setup!$C$4),MONTH(Setup!$C$4),DAY(Setup!$C$4)+((D30-1)*7)+(E30-WEEKDAY(DATE(YEAR(Setup!$C$4),MONTH(Setup!$C$4),DAY(Setup!$C$4)),1))) | J30: =I30+3 | K30: =(I30 + (7 - WEEKDAY(I30,1))) + 1 | L30: =F30*G30 | M30: Outcomes Not Met: W05 Project | N30: This student scored less than 80% on the W05 Project: Shopping Cart. Send a message to this student offering some form of help so he/she can be more successful on this assignment and resubmit.
A31: CSEPC110 | B31: Scheduled - Classwide | C31: Course Closing Reminder | D31: 7 | E31: 1 | H31: y | I31: =DATE(YEAR(Setup!$C$4),MONTH(Setup!$C$4),DAY(Setup!$C$4)+((D31-1)*7)+(E31-WEEKDAY(DATE(YEAR(Setup!$C$4),MONTH(Setup!$C$4),DAY(Setup!$C$4)),1))) | J31: =I31+3 | K31: =(I31 + (7 - WEEKDAY(I31,1))) + 1 | M31: Course Closing Reminder | N31: Send a message to your students, reminding them that the course is closing this week and of the due dates they must meet to get assignments in and applied to their final grade.
A32: CSEPC110 | B32: Scheduled - Classwide | C32: Registration Reminder 2 | D32: 7 | E32: 1 | H32: y | I32: =DATE(YEAR(Setup!$C$4),MONTH(Setup!$C$4),DAY(Setup!$C$4)+((D32-1)*7)+(E32-WEEKDAY(DATE(YEAR(Setup!$C$4),MONTH(Setup!$C$4),DAY(Setup!$C$4)),1))) | J32: =I32+3 | K32: =(I32 + (7 - WEEKDAY(I32,1))) + 1 | L32: 0 | M32: Registration Reminder 2 | N32: Send a message to all students, reminding them that registration for the next block is still open, but will be closing soon. Encourage them to go in and register as soon as possible.
A33: CSEPC110 | B33: Scheduled - Classwide | C33: End of Block Reminder | D33: 7 | E33: 2 | H33: y | I33: =DATE(YEAR(Setup!$C$4),MONTH(Setup!$C$4),DAY(Setup!$C$4)+((D33-1)*7)+(E33-WEEKDAY(DATE(YEAR(Setup!$C$4),MONTH(Setup!$C$4),DAY(Setup!$C$4)),1))) | J33: =I33+3 | K33: =(I33 + (7 - WEEKDAY(I33,1))) + 1 | L33: #VALUE! | M33: End of Block Reminder | N33: Remind Students the course will be closing, submit assignments by deadline, complete End-of-Course Evaluation

Sheet CSEPC110M
A1: Course | B1: Action Type | C1: Assignment | D1: Week of Outreach | E1: Day of Outreach | F1: Points Possible | G1: % + or - for Outreach | H1: Configured | I1: Start Date | J1: Due Date | K1: Expire Date | L1: Score | M1: Reason for Outreach Title (Drop Down in IMS) | N1: Description/Prompt in IMS | O1: Description/Prompt in IMS
A2: CSEPC110M | B2: New Student Added | C2: New Student Added | D2: 0 | E2: 2 | J2: =DATE(YEAR(Setup!$C$4),MONTH(Setup!$C$4),DAY(Setup!$C$4)+((D2-1)*7)+(E2-WEEKDAY(DATE(YEAR(Setup!$C$4),MONTH(Setup!$C$4),DAY(Setup!$C$4)),1))) | K2: =J2+3 | L2: =(J2 + (7 - WEEKDAY(J2,1))) + 1 | M2: =F2*G2 | N2: New Student Added | O2: Send a message to new students to welcome them to class and help them submit any assignments they missed.
A3: CSEPC110M | B3: Grader-Issued 0 | C3: 1.4 Project: Clever Stories | D3: 1 | E3: 1 | I3: 45906.999 | J3: =DATE(YEAR(Setup!$C$4),MONTH(Setup!$C$4),DAY(Setup!$C$4)+((D3-1)*7)+(E3-WEEKDAY(DATE(YEAR(Setup!$C$4),MONTH(Setup!$C$4),DAY(Setup!$C$4)),1))) | K3: =J3+3 | L3: =I3+14 | M3: =F3*G3 | N3: Outcomes Not Met: 1.4 Project | O3: This student did not meet the outcomes of this assignment. Send a message to this student offering some form of help so he/she can be more successful on this assignment and resubmit.
A4: CSEPC110M | B4: Grader-Issued 0 | C4: 2.4 Project: Meal Price Calculator | D4: 1 | E4: 1 | I4: 45913.999 | J4: =DATE(YEAR(Setup!$C$4),MONTH(Setup!$C$4),DAY(Setup!$C$4)+((D4-1)*7)+(E4-WEEKDAY(DATE(YEAR(Setup!$C$4),MONTH(Setup!$C$4),DAY(Setup!$C$4)),1))) | K4: =J4+3 | L4: =I4+14 | M4: =F4*G4 | N4: Outcomes Not Met: 2.4 Project | O4: This student did not meet the outcomes of this assignment. Send a message to this student offering some form of help so he/she can be more successful on this assignment and resubmit.
A5: CSEPC110M | B5: Grader-Issued 0 | C5: 3.4 Project: Adventure Game | D5: 1 | E5: 1 | I5: 45920.999 | J5: =DATE(YEAR(Setup!$C$4),MONTH(Setup!$C$4),DAY(Setup!$C$4)+((D5-1)*7)+(E5-WEEKDAY(DATE(YEAR(Setup!$C$4),MONTH(Setup!$C$4),DAY(Setup!$C$4)),1))) | K5: =J5+3 | L5: =I5+14 | M5: =F5*G5 | N5: Outcomes Not Met: 3.4 Project | O5: This student did not meet the outcomes of this assignment. Send a message to this student offering some form of help so he/she can be more successful on this assignment and resubmit.
A6: CSEPC110M | B6: Grader-Issued 0 | C6: 4.4 Project: Word Puzzle | D6: 1 | E6: 1 | I6: 45927.999 | J6: =DATE(YEAR(Setup!$C$4),MONTH(Setup!$C$4),DAY(Setup!$C$4)+((D6-1)*7)+(E6-WEEKDAY(DATE(YEAR(Setup!$C$4),MONTH(Setup!$C$4),DAY(Setup!$C$4)),1))) | K6: =J6+3 | L6: =I6+14 | M6: =F6*G6 | N6: Outcomes Not Met: 4.4 Project | O6: This student did not meet the outcomes of this assignment. Send a message to this student offering some form of help so he/she can be more successful on this assignment and resubmit.
A7: CSEPC110M | B7: Grader-Issued 0 | C7: 5.4 Project: Shopping Cart | D7: 1 | E7: 1 | I7: 45934.999 | J7: =DATE(YEAR(Setup!$C$4),MONTH(Setup!$C$4),DAY(Setup!$C$4)+((D7-1)*7)+(E7-WEEKDAY(DATE(YEAR(Setup!$C$4),MONTH(Setup!$C$4),DAY(Setup!$C$4)),1))) | K7: =J7+3 | L7: =I7+14 | M7: =F7*G7 | N7: Outcomes Not Met: 5.4 Project | O7: This student did not meet the outcomes of this assignment. Send a message to this student offering some form of help so he/she can be more successful on this assignment and resubmit.
A8: CSEPC110M | B8: Grader-Issued 0 | C8: A1.4 Project: Data Analysis | D8: 1 | E8: 1 | I8: 45941.999 | J8: =DATE(YEAR(Setup!$C$4),MONTH(Setup!$C$4),DAY(Setup!$C$4)+((D8-1)*7)+(E8-WEEKDAY(DATE(YEAR(Setup!$C$4),MONTH(Setup!$C$4),DAY(Setup!$C$4)),1))) | K8: =J8+3 | L8: =I8+14 | M8: =F8*G8 | N8: Outcomes Not Met: A1.4 Project | O8: This student did not meet the outcomes of this assignment. Send a message to this student offering some form of help so he/she can be more successful on this assignment and resubmit.
A9: CSEPC110M | B9: Grader-Issued 0 | C9: A2.4 Project: Windchill | D9: 1 | E9: 1 | I9: 45945.999 | J9: =DATE(YEAR(Setup!$C$4),MONTH(Setup!$C$4),DAY(Setup!$C$4)+((D9-1)*7)+(E9-WEEKDAY(DATE(YEAR(Setup!$C$4),MONTH(Setup!$C$4),DAY(Setup!$C$4)),1))) | K9: =J9+3 | L9: =I9+14 | M9: =F9*G9 | N9: Outcomes Not Met: A2.4 Project | O9: This student did not meet the outcomes of this assignment. Send a message to this student offering some form of help so he/she can be more successful on this assignment and resubmit.
A10: CSEPC110M | B10: High Performance | C10: 1.4 Project: Clever Stories | D10: 1 | E10: 1 | F10: 100 | G10: 1 | I10: 45906.999 | J10: =DATE(YEAR(Setup!$C$4),MONTH(Setup!$C$4),DAY(Setup!$C$4)+((D10-1)*7)+(E10-WEEKDAY(DATE(YEAR(Setup!$C$4),MONTH(Setup!$C$4),DAY(Setup!$C$4)),1))) | K10: =J10+3 | L10: =I10+14 | M10: =F10*G10 | N10: High-Performance: 1.4 Project | O10: This student met the outcomes of this assignment. Send a message of praise and encouragement for effort and good performance on this assignment.
A11: CSEPC110M | B11: High Performance | C11: 2.4 Project: Meal Price Calculator | D11: 1 | E11: 1 | F11: 100 | G11: 1 | I11: 45913.999 | J11: =DATE(YEAR(Setup!$C$4),MONTH(Setup!$C$4),DAY(Setup!$C$4)+((D11-1)*7)+(E11-WEEKDAY(DATE(YEAR(Setup!$C$4),MONTH(Setup!$C$4),DAY(Setup!$C$4)),1))) | K11: =J11+3 | L11: =I11+14 | M11: =F11*G11 | N11: High-Performance: 2.4 Project | O11: This student met the outcomes of this assignment. Send a message of praise and encouragement for effort and good performance on this assignment.
A12: CSEPC110M | B12: High Performance | C12: 3.4 Project: Adventure Game | D12: 1 | E12: 1 | F12: 100 | G12: 1 | I12: 45920.999 | J12: =DATE(YEAR(Setup!$C$4),MONTH(Setup!$C$4),DAY(Setup!$C$4)+((D12-1)*7)+(E12-WEEKDAY(DATE(YEAR(Setup!$C$4),MONTH(Setup!$C$4),DAY(Setup!$C$4)),1))) | K12: =J12+3 | L12: =I12+14 | M12: =F12*G12 | N12: High-Performance: 3.4 Project | O12: This student met the outcomes of this assignment. Send a message of praise and encouragement for effort and good performance on this assignment.
A13: CSEPC110M | B13: High Performance | C13: 4.4 Project: Word Puzzle | D13: 1 | E13: 1 | F13: 100 | G13: 1 | I13: 45927.999 | J13: =DATE(YEAR(Setup!$C$4),MONTH(Setup!$C$4),DAY(Setup!$C$4)+((D13-1)*7)+(E13-WEEKDAY(DATE(YEAR(Setup!$C$4),MONTH(Setup!$C$4),DAY(Setup!$C$4)),1))) | K13: =J13+3 | L13: =I13+14 | M13: =F13*G13 | N13: High-Performance: 4.4 Project | O13: This student met the outcomes of this assignment. Send a message of praise and encouragement for effort and good performance on this assignment.
A14: CSEPC110M | B14: High Performance | C14: 5.4 Project: Shopping Cart | D14: 1 | E14: 1 | F14: 100 | G14: 1 | I14: 45934.999 | J14: =DATE(YEAR(Setup!$C$4),MONTH(Setup!$C$4),DAY(Setup!$C$4)+((D14-1)*7)+(E14-WEEKDAY(DATE(YEAR(Setup!$C$4),MONTH(Setup!$C$4),DAY(Setup!$C$4)),1))) | K14: =J14+3 | L14: =I14+14 | M14: =F14*G14 | N14: High-Performance: 5.4 Project | O14: This student met the outcomes of this assignment. Send a message of praise and encouragement for effort and good performance on this assignment.
A15: CSEPC110M | B15: High Performance | C15: A1.4 Project: Data Analysis | D15: 1 | E15: 1 | F15: 100 | G15: 1 | I15: 45941.999 | J15: =DATE(YEAR(Setup!$C$4),MONTH(Setup!$C$4),DAY(Setup!$C$4)+((D15-1)*7)+(E15-WEEKDAY(DATE(YEAR(Setup!$C$4),MONTH(Setup!$C$4),DAY(Setup!$C$4)),1))) | K15: =J15+3 | L15: =I15+14 | M15: =F15*G15 | N15: High-Performance: A1.4 Project | O15: This student did the extra work to meet the outcomes of this advanced assignment. Send a message of praise and encouragement for effort and good performance on this assignment.
A16: CSEPC110M | B16: High Performance | C16: A2.4 Project: Windchill | D16: 1 | E16: 1 | F16: 100 | G16: 1 | I16: 45945.999 | J16: =DATE(YEAR(Setup!$C$4),MONTH(Setup!$C$4),DAY(Setup!$C$4)+((D16-1)*7)+(E16-WEEKDAY(DATE(YEAR(Setup!$C$4),MONTH(Setup!$C$4),DAY(Setup!$C$4)),1))) | K16: =J16+3 | L16: =I16+14 | M16: =F16*G16 | N16: High-Performance: A2.4 Project | O16: This student did the extra work to meet the outcomes of this advanced assignment. Send a message of praise and encouragement for effort and good performance on this assignment.
A17: CSEPC110M | B17: Quiz Question | C17: 1.2 Code-along Activity: ID Badge Generator; Question 1: Does the program you wrote run without errors; Answer: No | D17: 1 | E17: 1 | I17: 45904.999 | J17: =DATE(YEAR(Setup!$C$4),MONTH(Setup!$C$4),DAY(Setup!$C$4)+((D17-1)*7)+(E17-WEEKDAY(DATE(YEAR(Setup!$C$4),MONTH(Setup!$C$4),DAY(Setup!$C$4)),1))) | K17: =J17+3 | L17: =I17+14 | M17: =F17*G17 | N17: 1.2 Code-along: Program Has Errors | O17: This student indicated in their Code-along Activity that the program they created contains errors and/or is missing some of the required functionality. This could be predictive of challenges this student could encounter on their upcoming Project assignment. Check in with this student and offer help.
A18: CSEPC110M | B18: Quiz Question | C18: 2.2 Code-along Activity: Areas of Shapes; ; Question 1: Does the program you wrote run without errors; Answer: No | D18: 1 | E18: 1 | I18: 45911.999 | J18: =DATE(YEAR(Setup!$C$4),MONTH(Setup!$C$4),DAY(Setup!$C$4)+((D18-1)*7)+(E18-WEEKDAY(DATE(YEAR(Setup!$C$4),MONTH(Setup!$C$4),DAY(Setup!$C$4)),1))) | K18: =J18+3 | L18: =I18+14 | M18: =F18*G18 | N18: 2.2 Code-along: Program Has Errors | O18: This student indicated in their Code-along Activity that the program they created contains errors and/or is missing some of the required functionality. This could be predictive of challenges this student could encounter on their upcoming Project assignment. Check in with this student and offer help.
A19: CSEPC110M | B19: Quiz Question | C19: 3.2 Code-along Activity: Grade Calculator Program; Question 1: Does the program you wrote run without errors; Answer: No | D19: 1 | E19: 1 | I19: 45918.999 | J19: =DATE(YEAR(Setup!$C$4),MONTH(Setup!$C$4),DAY(Setup!$C$4)+((D19-1)*7)+(E19-WEEKDAY(DATE(YEAR(Setup!$C$4),MONTH(Setup!$C$4),DAY(Setup!$C$4)),1))) | K19: =J19+3 | L19: =I19+14 | M19: =F19*G19 | N19: 3.2 Code-along: Program Has Errors | O19: This student indicated in their Code-along Activity that the program they created contains errors and/or is missing some of the required functionality. This could be predictive of challenges this student could encounter on their upcoming Project assignment. Check in with this student and offer help.
A20: CSEPC110M | B20: Quiz Question | C20: 4.2 Code-along Activity: Guess My Number Game; Question 1: Does the program you wrote run without errors; Answer: No | D20: 1 | E20: 1 | I20: 45925.999 | J20: =DATE(YEAR(Setup!$C$4),MONTH(Setup!$C$4),DAY(Setup!$C$4)+((D20-1)*7)+(E20-WEEKDAY(DATE(YEAR(Setup!$C$4),MONTH(Setup!$C$4),DAY(Setup!$C$4)),1))) | K20: =J20+3 | L20: =I20+14 | M20: =F20*G20 | N20: 4.2 Code-along: Program Has Errors | O20: This student indicated in their Code-along Activity that the program they created contains errors and/or is missing some of the required functionality. This could be predictive of challenges this student could encounter on their upcoming Project assignment. Check in with this student and offer help.
A21: CSEPC110M | B21: Quiz Question | C21: 5.2 Code-along Activity: Lists of Numbers; Question 1: Does the program you wrote run without errors; Answer: No | D21: 1 | E21: 1 | I21: 45932.999 | J21: =DATE(YEAR(Setup!$C$4),MONTH(Setup!$C$4),DAY(Setup!$C$4)+((D21-1)*7)+(E21-WEEKDAY(DATE(YEAR(Setup!$C$4),MONTH(Setup!$C$4),DAY(Setup!$C$4)),1))) | K21: =J21+3 | L21: =I21+14 | M21: =F21*G21 | N21: 5.2 Code-along: Program Has Errors | O21: This student indicated in their Code-along Activity that the program they created contains errors and/or is missing some of the required functionality. This could be predictive of challenges this student could encounter on their upcoming Project assignment. Check in with this student and offer help.
A22: CSEPC110M | B22: Quiz Question | C22: A1.2 Code-along Activity: Human Resource System; Question 1: Does the program you wrote run without errors; Answer: No | D22: 1 | E22: 1 | I22: 45939.999 | J22: =DATE(YEAR(Setup!$C$4),MONTH(Setup!$C$4),DAY(Setup!$C$4)+((D22-1)*7)+(E22-WEEKDAY(DATE(YEAR(Setup!$C$4),MONTH(Setup!$C$4),DAY(Setup!$C$4)),1))) | K22: =J22+3 | L22: =I22+14 | M22: =F22*G22 | N22: A1.2 Code-along: Program Has Errors | O22: This student indicated in their Code-along Activity that the program they created contains errors and/or is missing some of the required functionality. This could be predictive of challenges this student could encounter on their upcoming Project assignment. Check in with this student and offer help.
A23: CSEPC110M | B23: Quiz Question | C23: A2.2 Code-along Activity: Personal Budget; Question 1: Does the program you wrote run without errors; Answer: No | D23: 1 | E23: 1 | I23: 45944.999 | J23: =DATE(YEAR(Setup!$C$4),MONTH(Setup!$C$4),DAY(Setup!$C$4)+((D23-1)*7)+(E23-WEEKDAY(DATE(YEAR(Setup!$C$4),MONTH(Setup!$C$4),DAY(Setup!$C$4)),1))) | K23: =J23+3 | L23: =I23+14 | M23: =F23*G23 | N23: A2.2 Code-along: Program Has Errors | O23: This student indicated in their Code-along Activity that the program they created contains errors and/or is missing some of the required functionality. This could be predictive of challenges this student could encounter on their upcoming Project assignment. Check in with this student and offer help.
A24: CSEPC110M | B24: Scheduled - Not Logged In | C24: Not Logged into Canvas | D24: 1 | E24: 4 | J24: =DATE(YEAR(Setup!$C$4),MONTH(Setup!$C$4),DAY(Setup!$C$4)+((D24-1)*7)+(E24-WEEKDAY(DATE(YEAR(Setup!$C$4),MONTH(Setup!$C$4),DAY(Setup!$C$4)),1))) | K24: =J24+3 | L24: =(J24 + (7 - WEEKDAY(J24,1))) + 1 | M24: =F24*G24 | N24: Not Logged Into Canvas | O24: Send a message (outside of Canvas) to students who have not logged into Canvas encouraging them to log in before Monday of Week 2.
A25: CSEPC110M | B25: Missing Assignment | C25: 1.1 Learning Activities: Input/Output | D25: 2 | E25: 1 | I25: 45904.999 | J25: =DATE(YEAR(Setup!$C$4),MONTH(Setup!$C$4),DAY(Setup!$C$4)+((D25-1)*7)+(E25-WEEKDAY(DATE(YEAR(Setup!$C$4),MONTH(Setup!$C$4),DAY(Setup!$C$4)),1))) | K25: =J25+3 | L25: =I25+14 | M25: =F25*G25 | N25: Missing 1.1 Learning Activities | O25: This student is falling behind the recommended schedule for this course. Check in with this student, offer help, and send a message of encouragement for the student to submit this assignment.
A26: CSEPC110M | B26: Missing Assignment | C26: 1.2 Code-along Activity: ID Badge Generator | D26: 2 | E26: 1 | I26: 45904.999 | J26: =DATE(YEAR(Setup!$C$4),MONTH(Setup!$C$4),DAY(Setup!$C$4)+((D26-1)*7)+(E26-WEEKDAY(DATE(YEAR(Setup!$C$4),MONTH(Setup!$C$4),DAY(Setup!$C$4)),1))) | K26: =J26+3 | L26: =I26+14 | M26: =F26*G26 | N26: Missing 1.2 Code-along Activity | O26: This student is falling behind the recommended schedule for this course. Check in with this student, offer help, and send a message of encouragement for the student to submit this assignment.
A27: CSEPC110M | B27: Missing Assignment | C27: 1.3.1 Quiz: Input/Output - Basic Understanding | D27: 2 | E27: 1 | I27: 45904.999 | J27: =DATE(YEAR(Setup!$C$4),MONTH(Setup!$C$4),DAY(Setup!$C$4)+((D27-1)*7)+(E27-WEEKDAY(DATE(YEAR(Setup!$C$4),MONTH(Setup!$C$4),DAY(Setup!$C$4)),1))) | K27: =J27+3 | L27: =I27+14 | M27: =F27*G27 | N27: Missing 1.3.1 Quiz: Input/Output | O27: This student is falling behind the recommended schedule for this course. Check in with this student, offer help, and send a message of encouragement for the student to submit this assignment.
A28: CSEPC110M | B28: Missing Assignment | C28: 1.3.2 Quiz: Input/Output - Application and Reasoning | D28: 2 | E28: 1 | I28: 45904.999 | J28: =DATE(YEAR(Setup!$C$4),MONTH(Setup!$C$4),DAY(Setup!$C$4)+((D28-1)*7)+(E28-WEEKDAY(DATE(YEAR(Setup!$C$4),MONTH(Setup!$C$4),DAY(Setup!$C$4)),1))) | K28: =J28+3 | L28: =I28+14 | M28: =F28*G28 | N28: Missing 1.3.2 Quiz: Input/Output | O28: This student is falling behind the recommended schedule for this course. Check in with this student, offer help, and send a message of encouragement for the student to submit this assignment.
A29: CSEPC110M | B29: Missing Assignment | C29: 1.4 Project: Clever Stories | D29: 2 | E29: 1 | I29: 45906.999 | J29: =DATE(YEAR(Setup!$C$4),MONTH(Setup!$C$4),DAY(Setup!$C$4)+((D29-1)*7)+(E29-WEEKDAY(DATE(YEAR(Setup!$C$4),MONTH(Setup!$C$4),DAY(Setup!$C$4)),1))) | K29: =J29+3 | L29: =I29+14 | M29: =F29*G29 | N29: Missing 1.4 Project: Clever Stories | O29: This student is falling behind the recommended schedule for this course. Check in with this student, offer help, and send a message of encouragement for the student to submit this assignment.
A30: CSEPC110M | B30: Missing Assignment | C30: 2.1 Learning Activities: Variables and Expressions | D30: 3 | E30: 1 | I30: 45911.999 | J30: =DATE(YEAR(Setup!$C$4),MONTH(Setup!$C$4),DAY(Setup!$C$4)+((D30-1)*7)+(E30-WEEKDAY(DATE(YEAR(Setup!$C$4),MONTH(Setup!$C$4),DAY(Setup!$C$4)),1))) | K30: =J30+3 | L30: =I30+14 | M30: =F30*G30 | N30: Missing 2.1 Learning Activities | O30: This student is falling behind the recommended schedule for this course. Check in with this student, offer help, and send a message of encouragement for the student to submit this assignment.
A31: CSEPC110M | B31: Missing Assignment | C31: 2.2 Code-along Activity: Areas of Shapes | D31: 3 | E31: 1 | I31: 45911.999 | J31: =DATE(YEAR(Setup!$C$4),MONTH(Setup!$C$4),DAY(Setup!$C$4)+((D31-1)*7)+(E31-WEEKDAY(DATE(YEAR(Setup!$C$4),MONTH(Setup!$C$4),DAY(Setup!$C$4)),1))) | K31: =J31+3 | L31: =I31+14 | M31: =F31*G31 | N31: Missing 2.2 Code-along Activity | O31: This student is falling behind the recommended schedule for this course. Check in with this student, offer help, and send a message of encouragement for the student to submit this assignment.
A32: CSEPC110M | B32: Missing Assignment | C32: 2.3.1 Quiz: Variables and Expressions - Basic Understanding | D32: 3 | E32: 1 | I32: 45911.999 | J32: =DATE(YEAR(Setup!$C$4),MONTH(Setup!$C$4),DAY(Setup!$C$4)+((D32-1)*7)+(E32-WEEKDAY(DATE(YEAR(Setup!$C$4),MONTH(Setup!$C$4),DAY(Setup!$C$4)),1))) | K32: =J32+3 | L32: =I32+14 | M32: =F32*G32 | N32: Missing 2.3.1 Quiz: Variables and Expressions | O32: This student is falling behind the recommended schedule for this course. Check in with this student, offer help, and send a message of encouragement for the student to submit this assignment.
A33: CSEPC110M | B33: Missing Assignment | C33: 2.3.2 Quiz: Variables and Expressions - Application and Reasoning | D33: 3 | E33: 1 | I33: 45911.999 | J33: =DATE(YEAR(Setup!$C$4),MONTH(Setup!$C$4),DAY(Setup!$C$4)+((D33-1)*7)+(E33-WEEKDAY(DATE(YEAR(Setup!$C$4),MONTH(Setup!$C$4),DAY(Setup!$C$4)),1))) | K33: =J33+3 | L33: =I33+14 | M33: =F33*G33 | N33: Missing 2.3.2 Quiz: Variables and Expressions | O33: This student is falling behind the recommended schedule for this course. Check in with this student, offer help, and send a message of encouragement for the student to submit this assignment.
A34: CSEPC110M | B34: Missing Assignment | C34: 2.4 Project: Meal Price Calculator | D34: 3 | E34: 1 | I34: 45913.999 | J34: =DATE(YEAR(Setup!$C$4),MONTH(Setup!$C$4),DAY(Setup!$C$4)+((D34-1)*7)+(E34-WEEKDAY(DATE(YEAR(Setup!$C$4),MONTH(Setup!$C$4),DAY(Setup!$C$4)),1))) | K34: =J34+3 | L34: =I34+14 | M34: =F34*G34 | N34: Missing 2.4 Project: Meal Price Calculator | O34: This student is falling behind the recommended schedule for this course. Check in with this student, offer help, and send a message of encouragement for the student to submit this assignment.
A35: CSEPC110M | B35: Missing Assignment | C35: 3.1 Learning Activities: Decisions | D35: 4 | E35: 1 | I35: 45918.999 | J35: =DATE(YEAR(Setup!$C$4),MONTH(Setup!$C$4),DAY(Setup!$C$4)+((D35-1)*7)+(E35-WEEKDAY(DATE(YEAR(Setup!$C$4),MONTH(Setup!$C$4),DAY(Setup!$C$4)),1))) | K35: =J35+3 | L35: =I35+14 | M35: =F35*G35 | N35: Missing 3.1 Learning Activities | O35: This student is falling behind the recommended schedule for this course. Check in with this student, offer help, and send a message of encouragement for the student to submit this assignment.
A36: CSEPC110M | B36: Missing Assignment | C36: 3.2 Code-along Activity: Grade Calculator Program | D36: 4 | E36: 1 | I36: 45918.999 | J36: =DATE(YEAR(Setup!$C$4),MONTH(Setup!$C$4),DAY(Setup!$C$4)+((D36-1)*7)+(E36-WEEKDAY(DATE(YEAR(Setup!$C$4),MONTH(Setup!$C$4),DAY(Setup!$C$4)),1))) | K36: =J36+3 | L36: =I36+14 | M36: =F36*G36 | N36: Missing 3.2 Code-along Activity | O36: This student is falling behind the recommended schedule for this course. Check in with this student, offer help, and send a message of encouragement for the student to submit this assignment.
... A54: CSEPC110M | B54: Missing Assignment | C54: A1.4 Project: Data Analysis | D54: 7 | E54: 1 | I54: 45941.999 | J54: =DATE(YEAR(Setup!$C$4),MONTH(Setup!$C$4),DAY(Setup!$C$4)+((D54-1)*7)+(E54-WEEKDAY(DATE(YEAR(Setup!$C$4),MONTH(Setup!$C$4),DAY(Setup!$C$4)),1))) | K54: =J54+3 | L54: =I54+14 | M54: =F54*G54 | N54: Missing A1.4 Project Data Analysis | O54: This student is falling behind the recommended schedule for this course. Check in with this student, offer help, and send a message of encouragement for the student to submit this assignment.
A55: CSEPC110M | B55: Scheduled - Classwide | C55: Course Closing Reminder | D55: 7 | E55: 1 | J55: =DATE(YEAR(Setup!$C$4),MONTH(Setup!$C$4),DAY(Setup!$C$4)+((D55-1)*7)+(E55-WEEKDAY(DATE(YEAR(Setup!$C$4),MONTH(Setup!$C$4),DAY(Setup!$C$4)),1))) | K55: =J55+3 | L55: =(J55 + (7 - WEEKDAY(J55,1))) + 1 | M55: =F55*G55 | N55: Course Closing Reminder | O55: Send a message to your students, reminding them that the course is closing this week and of the due dates they must meet to get assignments in and applied to their final grade.

Sheet CSE111
